Workbook

Sheet Read Me
A1: FRANCE MASTER'S SHORTLIST – Études en France catalogue (pulled 9 Oct 2026)
A2: Profile | B2: 4-year bachelor's (≈ Bac+4) with ~3 years' experience as an embedded systems engineer in biomedical devices
A3: What was searched | B3: ALL programs in the official Études en France catalogue of these degree types: Master (national), Master of Science (MSc), Mastère en sciences, Mastère spécialisé, Master recherche/professionnel, Diplôme d'ingénieur, PhD — 7,911 listings. Filtered by field/sub-field (electronics, signal & imaging, telecom, systems, industrial computing, engineering, medicine…) and by keywords → 999 relevant programs kept (arts/law/business/pharma/chemistry etc. removed).
A4: Data pulled per program | B4: Title, school, city, language, entry level, entry year, duration, tuition fee entered by the school, application window, whether a separate school application is required, website, requirements, direct catalogue link.
A5: Missing fees | B5: About half the listings have no fee in the catalogue (mostly public universities). These were filled with researched rules: the 2026-27 national fee decree, each university's exemption policy, and official school fee pages (sources in column "Fee basis" and the Sources sheet). "Fee confidence" tells you how sure the figure is.
A7: KEY FINDINGS
A8: 1. Cheapest route = public universities | B8: A national Master at a public university costs €3,950/yr for non-EU students in 2026-27 (official, service-public.gouv.fr). With an exemption it drops to ~€254-255/yr. Private schools and "MSc" programs cost €5,000-€18,000/yr.
A9: 2. BIG 2026 change: exemptions are now capped | B9: Decree n° 2026-385 (19 May 2026) caps fee exemptions at 30% of non-EU students per university in 2026-27, 25% in 2027-28 (your intake), 20% later. So budget €3,950/yr and treat €255 as a bonus. Apply for exemption at the same time as admission.
A10: 3. Most generous universities (2026-27) | B10: Sorbonne Université (says it can exempt all eligible applicants), Université de Toulouse (partial exemption for all), Université Grenoble Alpes / Grenoble INP (broad exemptions in 2026-27), Université de Lille (continues exemptions). See "University fee policies" sheet. Policies for Sept 2027 will be voted in spring/summer 2027 – re-check.
A11: 4. Your eligibility | B11: A 4-year bachelor's is usually treated as Bac+4 → you can enter Master year 1 (M1) almost everywhere, and many M2/MSc that accept Bac+4. Programs requiring Bac+5 (a Master) are marked red. Mastère Spécialisé (MS) accepts Bac+4 + 3 yrs experience — exactly your profile, but MS programs are expensive (€9k-€23k).
A12: 5. Grades | B12: Public French masters select on grades. If yours are average, compensate with: a strong SOP linking your embedded/biomedical work to the program, experience letters, a project portfolio (firmware, signal processing), a good IELTS (6.5+) and, for French-taught programs, a DELF/TCF B2. Apply widely (the EEF portal allows several choices).
A13: 6. "Reprise d'études" warning | B13: Some universities treat applicants who stopped studying 2+ years ago for work as "continuing education" with higher fees (e.g. Université de Pau states min €3,950+ for students resuming after a 2-yr break). Ask each university whether you will be enrolled under "formation initiale" before accepting.
A14: 7. Language | B14: Most cheap public masters are taught in FRENCH (B2 required). English-taught options are on the "English-taught" sheet. Learning French to B2 opens ~3x more low-fee options.
A15: 8. Apprenticeship programs | B15: Listings run by CFA/ITII (apprenticeship) are free to the student but need a French employer contract and residence permit — not realistic from abroad. Kept for completeness, marked in "Institution type".
A16: 9. PhD | B16: Only 1 relevant PhD listing appears in the catalogue. A French PhD needs a Master first; doctorate fee is €397/yr and PhDs are normally salaried (≈€2,100+/month gross). Plan: Master now → PhD later.
A17: 10. Deadlines | B17: Études en France applications for Sept 2027 are open in the catalogue from 1 Oct 2026 to 15 Mar 2027 (many schools close earlier, and "Extra school application" = Yes means you must ALSO apply on the school's own platform).
A19: SHEETS
A20: Top Picks (low fee) | B20: 261 programs: relevance ≥4, you are eligible, open, and could cost ≤ €6,000/yr. Start here.
A21: English-taught | B21: 192 open, eligible programs taught fully or partly in English.
A22: All Programs | B22: All 999 relevant programs, sorted by relevance → eligibility → lowest fee. Use the filter arrows.
A23: University fee policies | B23: 2026-27 exemption policy per university, with official sources.
A24: Summary | B24: Counts by field and fee band (live formulas on the All Programs sheet).
A25: Sources | B25: All official pages used.
A27: COLOUR LEGEND | B27: Fee: green ≤ €1,000 · yellow €1,001-6,000 · red > €6,000. Eligibility: green = eligible on level · red = needs a Master.
A28: Relevance | B28: ★★★★★ embedded / biomedical / health tech · ★★★★ electronics, signal, robotics, IoT, sensors · ★★★ AI, data, CS, cyber, energy · ★★ other engineering
A29: Est. total tuition | B29: Formula: Est. tuition per year × Years to finish (formula). Years are estimated from entry year (M1 entry = 2 yrs, M2 entry = 1 yr).
A30: Disclaimer | B30: Fees and policies change yearly; figures are 2026-27 (latest published). Always confirm on the school website before paying any deposit. Living costs (~€700-1,100/month, Campus France "proof of funds" ≈ €615/month) and CVEC (~€105) are extra.

Sheet Top Picks (low fee)
A1: # | B1: Relevance | C1: Relevance note | D1: Field (category) | E1: Program title (as in Études en France) | F1: Approx. English title (auto-translated) | G1: Degree type | H1: Institution / faculty | I1: University / group | J1: Campus / site | K1: City / postcode | L1: Institution type | M1: Teaching language | N1: Catalogue | O1: Entry level required | P1: Your eligibility (4-yr BS, 3 yrs exp.) | Q1: Entry year(s) | R1: Duration (months, per catalogue) | S1: Est. tuition / year non-EU (€) | T1: Lowest possible with exemption (€) | U1: Years to finish (est.) | V1: Est. total tuition (€) | W1: Fee basis & source | X1: Fee confidence | Y1: Fees found in catalogue (€) | Z1: Fee note from catalogue text | AA1: University exemption policy 2026-27 | AB1: Policy source | AC1: EEF status | AD1: Apply from | AE1: Apply until (EEF) | AF1: Extra school application required? | AG1: Program website | AH1: Requirements (excerpt) | AI1: Catalogue link
A2: 1 | B2: ★★★★★ | C2: 5 – Core fit (embedded/biomedical/health tech) | D2: IoT / Telecom / Networks | E2: Master indifférencié (recherche et professionnel) Master Computer Networks and IoT Systems | F2: Master Computer Networks and IoT Systems | G2: Master indifférencié (recherche et professionnel) | H2: Conservatoire national des arts et métiers - CNAM | J2: Cnam Etablissement Public - EPN5 Computer Science | K2: 75003 Paris | L2: Public school / institute | M2: English | N2: Taught in English | O2: Bac +4 / Bac +5 | P2: Eligible on level (4-yr BS ≈ Bac+4) | Q2: 1/2 | R2: 12 | S2: 3950 | T2: 255 | U2: 2 | V2: =IF(S2="","",S2*U2) | W2: Catalogue: €3,770. = national differentiated master fee (2026-27: €3,950). Exemption to ~€255 possible (university quota). | X2: High | Y2: 3770 | AC2: Open | AD2: 2026-10-01 | AE2: 2027-03-15 | AF2: Yes | AG2: https://master.roc.cnam.fr | AH2: International, European and French students willing to pursue a master degree in English, and possessing a Bachelor-level degree in one of these fields: Computer Science, Electronics, Computer Engineering, Electrical Eng | AI2: Open in EEF
A3: 2 | B3: ★★★★★ | C3: 5 – Core fit (embedded/biomedical/health tech) | D3: Biomedical / Health tech | E3: Master indifférencié (recherche et professionnel) mention Biomedical Engineering (BME) | F3: major: Biomedical Engineering (BME) | G3: Master indifférencié (recherche et professionnel) | H3: UFR des Sciences pharmaceutiques et biologiques | I3: Université de Montpellier | J3: Site de Montpellier | K3: 34090 Montpellier | L3: Public university | M3: English | N3: Taught in English | O3: Bac +4 | P3: Eligible on level (4-yr BS ≈ Bac+4) | Q3: 1 | R3: 12 | S3: 3950 | T3: 255 | U3: 2 | V3: =IF(S3="","",S3*U3) | W3: Not in catalogue. Public national master → 2026-27 differentiated fee €3,950; exemption to ~€254-255 depends on university quota (25% cap in 2027-28). | X3: Medium | AA3: Montpellier 2026-27: new non-EU entrants pay the differentiated fee unless individual exemption (limited). | AB3: https://www.umontpellier.fr/en/international/etudier-a-letranger/etudiants-internationaux-annee-universitaire-2026-2027/ | AC3: Open | AD3: 2026-10-01 | AE3: 2027-03-15 | AF3: No | AG3: https://idil.edu.umontpellier.fr/master-idil/les-parcours/ | AH3: Conditions d’accès Diplôme de licence dans la discipline choisie IDIL Niveau d’anglais B2 minimum CV et lettre de motivation 2 lettres de soutien d’un chercheur et/ou professeur (recommandé, mais non obligatoire) Estimat | AI3: Open in EEF
A4: 3 | B4: ★★★★★ | C4: 5 – Core fit (embedded/biomedical/health tech) | D4: Embedded systems / Electronics | E4: Master indifférencié (recherche et professionnel) mention Electronique, énergies électriques et automatique* parcours Electronique, Outils Libres pour l'instrumentation et les Systèmes Embarqués (ELISE) * | F4: major: Electronics, Energies Electrical & Automation* – track: Electronics, Outils Libres for Instrumentation & the Embedded Systems (ELISE) * | G4: Master indifférencié (recherche et professionnel) | H4: UFR Sciences et Techniques | I4: Université Marie et Louis Pasteur | J4: Site de Besançon | K4: 25030 BESANCON CEDEX | L4: Public university | M4: English | N4: Taught in English | O4: Bac +4 | P4: Eligible on level (4-yr BS ≈ Bac+4) | Q4: 1 | S4: 3950 | T4: 255 | U4: 2 | V4: =IF(S4="","",S4*U4) | W4: Not in catalogue. Public national master → 2026-27 differentiated fee €3,950; exemption to ~€254-255 depends on university quota (25% cap in 2027-28). | X4: Medium | AA4: UMLP: individual exemption requests assessed on personal resources. | AB4: https://www.umlp.fr/sites/default/files/2026-07-02-page-droits-differencies-vf.pdf | AC4: Open | AD4: 2026-10-01 | AE4: 2027-03-15 | AF4: No | AG4: https://formations.univ-fcomte.fr/fr/formations/feuilleter-le-catalogue/master-lmd-XB/master-electronique-energie-electrique-automatique-M4QUAZ0D.html | AH4: C langage programming, digital electronics, microcontroller programming, analog electronics, instrumentation, Python programming, signal processing, mathematics (basic algebra and analysis), Linux operating system Langue | AI4: Open in EEF
A5: 4 | B5: ★★★★★ | C5: 5 – Core fit (embedded/biomedical/health tech) | D5: Biomedical / Health tech | E5: Master indifférencié (recherche et professionnel) Sciences, Technologies, Santé mention Biologie Santé parcours Bioingénierie Moléculaire et Cellulaire | F5: Science, Technology, Health (STS) – major: Biology-Health – track: Bioengineering Molecular & Cellular | G5: Master indifférencié (recherche et professionnel) | H5: UFR de Chimie et Biologie | I5: Université de Grenoble Alpes | J5: Site de Grenoble - Campus de Saint Martin d'Hères | L5: Public university | M5: English | N5: Taught in English | O5: Bac +4 | P5: Eligible on level (4-yr BS ≈ Bac+4) | Q5: 1 | S5: 3950 | T5: 255 | U5: 2 | V5: =IF(S5="","",S5*U5) | W5: Not in catalogue. Public national master → 2026-27 differentiated fee €3,950; exemption to ~€254-255 depends on university quota (25% cap in 2027-28). | X5: Medium | AA5: UGA (incl. Grenoble INP masters): 2026-27 broad exemptions on request (pay national €254). From 2027-28 the decree caps apply; exemptions based on resources. | AB5: https://www.univ-grenoble-alpes.fr/actualites/a-la-une/actualites-universite/etudiants-internationaux-ce-que-change-le-nouveau-decret-sur-les-droits-d-inscription-a-l-uga-1775870.kjsp | AC5: Open | AD5: 2026-10-01 | AE5: 2027-03-15 | AF5: No | AG5: https://formations.univ-grenoble-alpes.fr/fr/offre-de-formation/master-XB/master-biologie-sante-IAQKB0GE/parcours-molecular-and-cellular-biology-1re-annee-IK43J2QV.html | AH5: The "Bioingénierie Moléculaire et Cellulaire" M1 program is open to students having completed a bachelor’s degree in Sciences or are enrolled in the ﬁnal semester of a bachelor’s program in Sciences with a solid backgrou | AI5: Open in EEF
A6: 5 | B6: ★★★★★ | C6: 5 – Core fit (embedded/biomedical/health tech) | D6: Biomedical / Health tech | E6: Master indifférencié (recherche et professionnel) Sciences, Technologies, Santé mention Ingénierie de la santé parcours Bio Health Engineering | F6: Science, Technology, Health (STS) – major: Health Engineering – track: Bio Health Engineering | G6: Master indifférencié (recherche et professionnel) | H6: UFR Médecine - Pharmacie | I6: Université de Grenoble Alpes | J6: Site de Grenoble - Campus de La Merci - La Tronche | L6: Public university | M6: English | N6: Taught in English | O6: Bac +4 / Bac +5 | P6: Eligible on level (4-yr BS ≈ Bac+4) | Q6: 1/2 | S6: 3950 | T6: 255 | U6: 2 | V6: =IF(S6="","",S6*U6) | W6: Not in catalogue. Public national master → 2026-27 differentiated fee €3,950; exemption to ~€254-255 depends on university quota (25% cap in 2027-28). | X6: Medium | AA6: UGA (incl. Grenoble INP masters): 2026-27 broad exemptions on request (pay national €254). From 2027-28 the decree caps apply; exemptions based on resources. | AB6: https://www.univ-grenoble-alpes.fr/actualites/a-la-une/actualites-universite/etudiants-internationaux-ce-que-change-le-nouveau-decret-sur-les-droits-d-inscription-a-l-uga-1775870.kjsp | AC6: Open | AD6: 2026-10-01 | AE6: 2027-03-15 | AF6: No | AG6: https://formations.univ-grenoble-alpes.fr/fr/catalogue-2021/master-XB/master-ingenierie-de-la-sante-IAQKSXOB.html | AH6: Requirement M1: - Strong theoritical and practical skills in biology or biochemistry or pharmaceutical sciences or biotechnologies. - B2 level in english mandatory. Requirement M2: - Strong theoritical and practical skil | AI6: Open in EEF
A7: 6 | B7: ★★★★★ | C7: 5 – Core fit (embedded/biomedical/health tech) | D7: Biomedical / Health tech | E7: Master indifférencié (recherche et professionnel) Sciences, technologies, santé mention sciences du vivant parcours Biomedical and Computational Sciences in Ageing (imAGEin) | F7: Science, Technology, Health (STS) – major: Sciences of Life – track: Biomedical and Computational Sciences in Ageing (imAGEin) | G7: Master indifférencié (recherche et professionnel) | H7: Sciences | I7: Université Côte d'Azur | J7: Site de Nice | L7: Public university | M7: English | N7: General | O7: Bac +3 | P7: Eligible on level (4-yr BS ≈ Bac+4) | Q7: 1 | S7: 3950 | T7: 255 | U7: 2 | V7: =IF(S7="","",S7*U7) | W7: Not in catalogue. Public national master → 2026-27 differentiated fee €3,950; exemption to ~€254-255 depends on university quota (25% cap in 2027-28). | X7: Medium | AC7: Open | AD7: 2026-10-01 | AE7: 2027-03-15 | AF7: Yes | AG7: https://life.univ-cotedazur.fr/international/imagein | AH7: Consulter le site web | AI7: Open in EEF
A8: 7 | B8: ★★★★★ | C8: 5 – Core fit (embedded/biomedical/health tech) | D8: IoT / Telecom / Networks | E8: Master Sciences, technologies, santé mention informatique parcours Internet of Things | F8: Master Science, Technology, Health (STS) – major: Computer Science – track: Internet of Things | G8: Master indifférencié (recherche et professionnel) | H8: UFR Sciences, Techniques et Gestion de l'Industrie | I8: Université Marie et Louis Pasteur | J8: Site de Montbéliard | K8: 25211 MONTBELIARD CEDEX | L8: Public university | M8: English | N8: General | O8: Bac +4 / Bac +5 | P8: Eligible on level (4-yr BS ≈ Bac+4) | Q8: 1/2 | R8: 12 | S8: 3950 | T8: 255 | U8: 2 | V8: =IF(S8="","",S8*U8) | W8: Not in catalogue. Public national master → 2026-27 differentiated fee €3,950; exemption to ~€254-255 depends on university quota (25% cap in 2027-28). | X8: Medium | Z8: (Pour information, le montant de la CVEC, pour la rentrée 2026-2027, était de 105€) … (Pour information, le montant de la CVEC, pour la rentrée 2025-2026, était de 105€) | AA8: UMLP: individual exemption requests assessed on personal resources. | AB8: https://www.umlp.fr/sites/default/files/2026-07-02-page-droits-differencies-vf.pdf | AC8: Open | AD8: 2026-10-01 | AE8: 2027-03-15 | AF8: No | AG8: https://stgi.umlp.fr/ | AH8: Le Master Internet of Things (IOT) est un Master en Informatique spécialisé dans le développement des objets communiquants. Il est attendu des candidats en M1 : Licence Informatique avec de bonnes connaissances en algori | AI8: Open in EEF
A9: 8 | B9: ★★★★★ | C9: 5 – Core fit (embedded/biomedical/health tech) | D9: Biomedical / Health tech | E9: Master indifférencié (recherche et professionnel) Sciences, technologies, santé mention Biotechnologies parcours Biomédicaments : conception et production | F9: Science, Technology, Health (STS) – major: Biotechnologies – track: Biodrugs : Design & Production | G9: Master indifférencié (recherche et professionnel) | H9: Faculté de pharmacie | I9: Université de Strasbourg | J9: Site de Illkirch-Graffenstaden | L9: Public university | M9: French & English | N9: General | O9: Bac +4 | P9: Eligible on level (4-yr BS ≈ Bac+4) | Q9: 1 | S9: 3950 | T9: 255 | U9: 2 | V9: =IF(S9="","",S9*U9) | W9: Catalogue: €3,950. = national differentiated master fee (2026-27: €3,950). Exemption to ~€255 possible (university quota). | X9: High | Y9: 3950 | AA9: Unistra: master entrants who did not do their licence at Unistra pay the differentiated fee (€3,950). | AB9: https://www.unistra.fr/fr/node/8168 | AC9: Open | AD9: 2026-10-01 | AE9: 2027-03-15 | AF9: No | AG9: https://pharmacie.unistra.fr | AH9: Entrée en M1 avoir effectué un curus en : - biologie cellulaire et moléculaire, biochimie, - avoir des bases en chimie Entrée en M2 avoir effectué un cursus en - biologie moléculaire et cellulaire avancée, - avoir des ba | AI9: Open in EEF
A10: 9 | B10: ★★★★★ | C10: 5 – Core fit (embedded/biomedical/health tech) | D10: Biomedical / Health tech | E10: Master indifférencié (recherche et professionnel) Sciences, technologies, santé mention sciences du vivant parcours Bioinformatique et Bioimagerie Structurale | F10: Science, Technology, Health (STS) – major: Sciences of Life – track: Bioinformatics & Bioimagerie Structural | G10: Master indifférencié (recherche et professionnel) | H10: Faculté des sciences de la vie | I10: Université de Strasbourg | J10: Site de Strasbourg | K10: 67000 Strasbourg | L10: Public university | M10: French & English | N10: General | O10: Bac +4 / Bac +5 | P10: Eligible on level (4-yr BS ≈ Bac+4) | Q10: 1/2 | S10: 3950 | T10: 255 | U10: 2 | V10: =IF(S10="","",S10*U10) | W10: Catalogue: €3,950. = national differentiated master fee (2026-27: €3,950). Exemption to ~€255 possible (university quota). | X10: High | Y10: 3950 | AA10: Unistra: master entrants who did not do their licence at Unistra pay the differentiated fee (€3,950). | AB10: https://www.unistra.fr/fr/node/8168 | AC10: Open | AD10: 2026-10-01 | AE10: 2027-03-15 | AF10: No | AG10: http://sciencesvie.unistra.fr/ | AH10: M1 : Cette formation s’adresse aux étudiants désirant acquérir une formation pluridisciplinaire alliant une culture biologique à une maîtrise ou une expertise de plusieurs outils et méthodes informatiques, bioinformatiqu | AI10: Open in EEF
A11: 10 | B11: ★★★★★ | C11: 5 – Core fit (embedded/biomedical/health tech) | D11: IoT / Telecom / Networks | E11: Master indifférencié (recherche et professionnel) Sciences, technologies, santé mention Traitement du signal et des images parcours EUR Smart IoT | F11: Science, Technology, Health (STS) – major: Signal & Image Processing – track: EUR Smart IoT | G11: Master indifférencié (recherche et professionnel) | H11: UFR de sciences fondamentales et appliquées - Université de Poitiers | I11: Université de Poitiers | J11: Site de Poitiers | L11: Public university | M11: French & English | N11: Taught in English | O11: Bac +4 / Bac +5 | P11: Eligible on level (4-yr BS ≈ Bac+4) | Q11: 1/2 | S11: 3950 | T11: 255 | U11: 2 | V11: =IF(S11="","",S11*U11) | W11: Catalogue: €3,950. = national differentiated master fee (2026-27: €3,950). Exemption to ~€255 possible (university quota). | X11: High | Y11: 3950 | AC11: Open | AD11: 2026-10-01 | AE11: 2027-03-15 | AF11: No | AG11: https://www.unilim.fr/gradschool-ceramics-ict/formation/smart-iot/ | AH11: Year 1 The admissions committee will focus in particular on the candidate’s grades in subjects related to the intended field of study and on the candidate’s ability to articulate their motivations and career goals. Minim | AI11: Open in EEF
A12: 11 | B12: ★★★★★ | C12: 5 – Core fit (embedded/biomedical/health tech) | D12: Biomedical / Health tech | E12: Master Sciences, technologies, santé, mention Ingéniérie de la santé parcours Biomatériaux et bio ingénierie pour la santé | F12: Master Science, Technology, Health (STS), – major: Engineering of the Health – track: Biomaterials & bio Engineering for Health | G12: Master indifférencié (recherche et professionnel) | H12: Faculté de chirurgie dentaire | I12: Université de Strasbourg | J12: Site de Strasbourg | L12: Public university | M12: French & English | N12: General | O12: Bac +4 / Bac +5 | P12: Eligible on level (4-yr BS ≈ Bac+4) | Q12: 1/2 | S12: 3950 | T12: 255 | U12: 2 | V12: =IF(S12="","",S12*U12) | W12: Catalogue: €3,950. = national differentiated master fee (2026-27: €3,950). Exemption to ~€255 possible (university quota). | X12: High | Y12: 3950 | AA12: Unistra: master entrants who did not do their licence at Unistra pay the differentiated fee (€3,950). | AB12: https://www.unistra.fr/fr/node/8168 | AC12: Open | AD12: 2026-10-01 | AE12: 2027-03-15 | AF12: No | AG12: https://chirurgie-dentaire.unistra.fr/ | AH12: Formation à enseignement mixte : français/anglais. Niveau de langue (anglais B1, français C1) | AI12: Open in EEF
A13: 12 | B13: ★★★★★ | C13: 5 – Core fit (embedded/biomedical/health tech) | D13: Biomedical / Health tech | E13: Master Sciences, technologies, santé, mention Ingénierie de la santé parcours Jumeaux numériques pour la santé | F13: Master Science, Technology, Health (STS), – major: Health Engineering – track: Jumeaux Digital for the Health | G13: Master indifférencié (recherche et professionnel) | H13: Université de technologie de Compiègne | J13: Site de Compiègne | L13: Public university | M13: French & English | N13: General | O13: Bac +4 / Bac +5 | P13: Eligible on level (4-yr BS ≈ Bac+4) | Q13: 1/2 | S13: 3950 | T13: 255 | U13: 2 | V13: =IF(S13="","",S13*U13) | W13: Catalogue: €3,950. = national differentiated master fee (2026-27: €3,950). Exemption to ~€255 possible (university quota). | X13: High | Y13: 3950 | AC13: Open | AD13: 2026-10-01 | AE13: 2027-03-15 | AF13: No | AH13: Parcours DTH Mentions de licences conseillées : Informatique Mathématiques Physique Mécanique Sciences et technologies Sciences pour l'ingénieur Attendus : Avoir des compétences en mathématiques appliquées, en mécanique | AI13: Open in EEF
A14: 13 | B14: ★★★★★ | C14: 5 – Core fit (embedded/biomedical/health tech) | D14: Biomedical / Health tech | E14: Master indifférencié (recherche et professionnel) Sciences, technologies, santé mention Electronique, énergie électrique, automatique parcours Ingénierie pour la santé | F14: Science, Technology, Health (STS) – major: Electronics, Electrical Energy & Automation (EEA) – track: Engineering for Health | G14: Master indifférencié (recherche et professionnel) | H14: Sciences et Ingénierie | I14: Sorbonne Université | J14: Site de Paris | L14: Public university | M14: French & English | N14: General | O14: Bac +4 / Bac +5 | P14: Eligible on level (4-yr BS ≈ Bac+4) | Q14: 1/2 | S14: 3950 | T14: 255 | U14: 2 | V14: =IF(S14="","",S14*U14) | W14: Not in catalogue. Public national master → 2026-27 differentiated fee €3,950; exemption to ~€254-255 depends on university quota (25% cap in 2027-28). | X14: Medium | AA14: Board vote 7 Jul 2026: Sorbonne Université says it can exempt all eligible non-EU applicants (pay same as EU, ~€254) for 2026-27. | AB14: https://www.sorbonne-universite.fr/actualites/le-conseil-dadministration-de-sorbonne-universite-vote-lunanimite-le-7-juillet-2026-sa | AC14: Open | AD14: 2026-10-01 | AE14: 2027-03-15 | AF14: No | AG14: https://masters-sdi.sorbonne-universite.fr/electronique-energie-electrique-automatique | AI14: Open in EEF
A15: 14 | B15: ★★★★★ | C15: 5 – Core fit (embedded/biomedical/health tech) | D15: Embedded systems / Electronics | E15: Master indifférencié (recherche et professionnel) Sciences, technologies, santé mention Electronique, énergie électrique, automatique parcours Microélectronique Intégration des Systèmes Temps Réels et Embarqués (EEA MISTRE) | F15: Science, Technology, Health (STS) – major: Electronics, Electrical Energy & Automation (EEA) – track: Microelectronics Integration of Systems Real-Times & Embedded (EEA MISTRE) | G15: Master indifférencié (recherche et professionnel) | H15: UFR de Physique, ingénierie, terre, environnement, mécanique | I15: Université de Grenoble Alpes | J15: Site de Grenoble - Polygone scientifique - GreEn-ER | L15: Public university | M15: French & English | N15: General | O15: Bac +4 / Bac +5 | P15: Eligible on level (4-yr BS ≈ Bac+4) | Q15: 1/2 | S15: 3950 | T15: 255 | U15: 2 | V15: =IF(S15="","",S15*U15) | W15: Not in catalogue. Public national master → 2026-27 differentiated fee €3,950; exemption to ~€254-255 depends on university quota (25% cap in 2027-28). | X15: Medium | AA15: UGA (incl. Grenoble INP masters): 2026-27 broad exemptions on request (pay national €254). From 2027-28 the decree caps apply; exemptions based on resources. | AB15: https://www.univ-grenoble-alpes.fr/actualites/a-la-une/actualites-universite/etudiants-internationaux-ce-que-change-le-nouveau-decret-sur-les-droits-d-inscription-a-l-uga-1775870.kjsp | AC15: Open | AD15: 2026-10-01 | AE15: 2027-03-15 | AF15: No | AG15: https://formations.univ-grenoble-alpes.fr/fr/catalogue-2021/master-XB/master-electronique-energie-electrique-automatique-IFZ3DRB9/parcours-microelectronique-integration-des-systemes-temps-reels-embarques-mistre-1re-et-2e-annees-IFZ5TP7C.html | AH15: Master 1 : - Les candidats titulaires d'un diplôme de BAC+5 au moment de la candidature ne seront pas admis en master 1. Seules les candidatures de BAC+3 ou BAC+4 seront considérées. - Prérequis : Electronique, automatiq | AI15: Open in EEF
A16: 15 | B16: ★★★★★ | C16: 5 – Core fit (embedded/biomedical/health tech) | D16: Embedded systems / Electronics | E16: Master indifférencié (recherche et professionnel) Sciences, technologies, santé mention Electronique, énergie électrique, automatique parcours Systèmes Communicants | F16: Science, Technology, Health (STS) – major: Electronics, Electrical Energy & Automation (EEA) – track: Systems Communicating | G16: Master indifférencié (recherche et professionnel) | H16: Sciences et Ingénierie | I16: Sorbonne Université | J16: Site de Paris | L16: Public university | M16: French & English | N16: General | O16: Bac +4 / Bac +5 | P16: Eligible on level (4-yr BS ≈ Bac+4) | Q16: 1/2 | S16: 3950 | T16: 255 | U16: 2 | V16: =IF(S16="","",S16*U16) | W16: Not in catalogue. Public national master → 2026-27 differentiated fee €3,950; exemption to ~€254-255 depends on university quota (25% cap in 2027-28). | X16: Medium | AA16: Board vote 7 Jul 2026: Sorbonne Université says it can exempt all eligible non-EU applicants (pay same as EU, ~€254) for 2026-27. | AB16: https://www.sorbonne-universite.fr/actualites/le-conseil-dadministration-de-sorbonne-universite-vote-lunanimite-le-7-juillet-2026-sa | AC16: Open | AD16: 2026-10-01 | AE16: 2027-03-15 | AF16: No | AG16: https://masters-sdi.sorbonne-universite.fr/electronique-energie-electrique-automatique | AI16: Open in EEF
A17: 16 | B17: ★★★★★ | C17: 5 – Core fit (embedded/biomedical/health tech) | D17: Biomedical / Health tech | E17: Master Sciences de la santé mention Ingénierie de la santé | F17: Master Sciences of the Health – major: Health Engineering | G17: Master indifférencié (recherche et professionnel) | H17: UFR des Sciences Fondamentales et Biomédicales | I17: Université Paris Cité | J17: Site de Paris | K17: 75006 Paris | L17: Public university | M17: French & English | N17: General | O17: Bac +4 | P17: Eligible on level (4-yr BS ≈ Bac+4) | Q17: 1 | S17: 3950 | T17: 255 | U17: 2 | V17: =IF(S17="","",S17*U17) | W17: Not in catalogue. Public national master → 2026-27 differentiated fee €3,950; exemption to ~€254-255 depends on university quota (25% cap in 2027-28). | X17: Medium | AA17: Paris Cité historically exempted non-EU master students (paid EU rate). 2026-27/2027-28 policy not yet published – confirm. | AB17: https://u-paris.fr/droits-dinscription-tarifs-exonerations/ | AC17: Open | AD17: 2026-10-01 | AE17: 2027-03-15 | AF17: Yes | AG17: https://odf.u-paris.fr/fr/offre-de-formation/master-XB/sciences-technologies-sante-STS/ingenierie-de-la-sante-K2NDJ7KW.html | AH17: All courses are taught in English, so candidates must demonstrate a perfect command of English (C1 level certificate required) with no French prerequisites for non-French speaking students. Candidates must: - excel in th | AI17: Open in EEF
A18: 17 | B18: ★★★★★ | C18: 5 – Core fit (embedded/biomedical/health tech) | D18: Embedded systems / Electronics | E18: Master indifférencié (recherche et professionnel) Sciences et technologies mention Electronique, énergie électrique, automatique parcours Systèmes Embarqués (SE) | F18: Science & Technology – major: Electronics, Electrical Energy & Automation (EEA) – track: Embedded Systems (SE) | G18: Master indifférencié (recherche et professionnel) | H18: Campus scientifique de BEAULIEU | I18: Université de Rennes | J18: Site de Rennes - ISTIC | K18: 35042 RENNES Cedex | L18: Public university | M18: French | N18: General | O18: Bac +4 | P18: Eligible on level (4-yr BS ≈ Bac+4) | Q18: 1 | R18: 12 | S18: 3950 | T18: 255 | U18: 2 | V18: =IF(S18="","",S18*U18) | W18: Catalogue: €3,950. = national differentiated master fee (2026-27: €3,950). Exemption to ~€255 possible (university quota). | X18: High | Y18: 3950 | Z18: ue, il faudra vous acquitter obligatoirement des frais d'inscription d'un montant de 3950 euros pour vous inscrire dans la formation | AC18: Open | AD18: 2026-10-01 | AE18: 2027-03-15 | AF18: No | AG18: https://istic.univ-rennes.fr/master-eeea-electronique-energie-electrique-automatique | AH18: Prérequis :Les candidats doivent disposer de bases solides en électronique analogique et numérique, en outils mathématiques pour le traitement du signal ainsi qu'en programmation. Profil attendu : Etudiant.e de niveau Ba | AI18: Open in EEF
A19: 18 | B19: ★★★★★ | C19: 5 – Core fit (embedded/biomedical/health tech) | D19: Embedded systems / Electronics | E19: Master indifférencié (recherche et professionnel) Sciences, technologies, santé mention génie industriel parcours Systèmes Embarqués et Technologies d'Intelligence Artificielle | F19: Science, Technology, Health (STS) – major: Industrial Engineering – track: Embedded Systems & Technologies d'Artificial Intelligence | G19: Master indifférencié (recherche et professionnel) | H19: Institut supérieur des sciences et techniques | I19: Université Picardie Jules Verne Amiens | J19: Site de Saint-Quentin | K19: 02315 Saint Quentin cedex | L19: Public school / institute | M19: French | N19: General | O19: Bac +4 | P19: Eligible on level (4-yr BS ≈ Bac+4) | Q19: 1 | R19: 12 | S19: 3950 | T19: 255 | U19: 2 | V19: =IF(S19="","",S19*U19) | W19: Catalogue: €3,950. = national differentiated master fee (2026-27: €3,950). Exemption to ~€255 possible (university quota). | X19: High | Y19: 3950 | AC19: Open | AD19: 2026-10-01 | AE19: 2027-03-15 | AF19: No | AG19: https://www.insset.u-picardie.fr/ | AH19: Niveau de test de compétence en Francais requis B2 Le tarif indiqué est celui de l'année universitaire 2026/2027 et, est susceptible d'etre modifié pour la rentrée 2027/2028 Pré-requis nécessaires en programmation inform | AI19: Open in EEF
A20: 19 | B20: ★★★★★ | C20: 5 – Core fit (embedded/biomedical/health tech) | D20: Embedded systems / Electronics | E20: Master indifférencié (recherche et professionnel) Sciences, technologies, santé mention informatique parcours LSE : logiciel pour systèmes embarqués | F20: Science, Technology, Health (STS) – major: Computer Science – track: LSE : Software for Embedded Systems | G20: Master indifférencié (recherche et professionnel) | H20: UFR sciences et techniques | I20: Université de Bretagne Occidentale | J20: Site de Brest | L20: Public university | M20: French | N20: General | O20: Bac +4 / Bac +5 | P20: Eligible on level (4-yr BS ≈ Bac+4) | Q20: 1/2 | R20: 12 | S20: 3950 | T20: 255 | U20: 2 | V20: =IF(S20="","",S20*U20) | W20: Catalogue: €3,950. = national differentiated master fee (2026-27: €3,950). Exemption to ~€255 possible (university quota). | X20: High | Y20: 3950 | AC20: Open | AD20: 2026-10-01 | AE20: 2027-03-15 | AF20: No | AG20: http://www.univ-brest.fr/ufr-sciences | AH20: L'université de Bretagne occidentale demande de présenter un Test de connaissance en français pour tous les candidats dont une des langues officielles n'est pas le français. Pour les pays où le français n'est pas la seul | AI20: Open in EEF
A21: 20 | B21: ★★★★★ | C21: 5 – Core fit (embedded/biomedical/health tech) | D21: Biomedical / Health tech | E21: Master indifférencié (recherche et professionnel) Sciences, technologies, santé mention Ingénierie de la santé parcours Technologies biomédicales et territoires de santé | F21: Science, Technology, Health (STS) – major: Health Engineering – track: Technologies biomédicales & Territories of Health | G21: Master indifférencié (recherche et professionnel) | H21: Université de technologie de Compiègne | J21: Site de Compiègne | L21: Public university | M21: French | N21: General | O21: Bac +4 / Bac +5 | P21: Eligible on level (4-yr BS ≈ Bac+4) | Q21: 1/2 | S21: 3950 | T21: 255 | U21: 2 | V21: =IF(S21="","",S21*U21) | W21: Catalogue: €3,950. = national differentiated master fee (2026-27: €3,950). Exemption to ~€255 possible (university quota). | X21: High | Y21: 3950 | AC21: Open | AD21: 2026-10-01 | AE21: 2027-03-15 | AF21: No | AG21: https://www.utc.fr/formations/diplome-de-master/mention-ingenierie-de-la-sante-ids/parcours-technologies-biomedicales-et-territoires-de-sante-tbts/ | AH21: Pour les parcours DMAR et TBTS Attention, le recrutement en M1 est commun. Ainsi, en candidatant sur l’un vous candidatez également sur l’autre, pas besoin de déposer votre dossier de candidature deux fois. Mentions de l | AI21: Open in EEF
A22: 21 | B22: ★★★★★ | C22: 5 – Core fit (embedded/biomedical/health tech) | D22: Embedded systems / Electronics | E22: Master indifférencié (recherche et professionnel) Sciences, technologies, santé mention Ingénierie des systèmes complexes parcours Robotique, Intelligence artificielle et Systèmes Embarqués (RISE) | F22: Science, Technology, Health (STS) – major: Complex Systems Engineering – track: Robotics, Artificial Intelligence & Embedded Systems (RISE) | G22: Master indifférencié (recherche et professionnel) | H22: UFR de sciences et techniques | I22: Université de Toulon | J22: Site de La Garde | K22: 83130 La Garde UFR SCIENCES ET TECH | L22: Public university | M22: French | N22: General | O22: Bac +4 | P22: Eligible on level (4-yr BS ≈ Bac+4) | Q22: 1 | R22: 12 | S22: 3950 | T22: 255 | U22: 2 | V22: =IF(S22="","",S22*U22) | W22: Catalogue: €3,950. = national differentiated master fee (2026-27: €3,950). Exemption to ~€255 possible (university quota). | X22: High | Y22: 3950 | AC22: Open | AD22: 2026-10-01 | AE22: 2027-03-15 | AF22: No | AG22: https://formations.univ-tln.fr/fr/offre-de-formation/master-XB/master-ingenierie-des-systemes-complexes-LO8RGPP1/master-ingenierie-des-systemes-complexes-parcours-robotique-intelligente-et-systemes-embarques-LPZRY65U.html | AH22: Attendus administratifs : Niveau B2 de langue française exigé Attendus pédagogiques : solides connaissances en maths-physiques, notions de programmation, sens physique. Un nombre limité de cours magistraux sont susceptib | AI22: Open in EEF
A23: 22 | B23: ★★★★★ | C23: 5 – Core fit (embedded/biomedical/health tech) | D23: Biomedical / Health tech | E23: Master indifférencié (recherche et professionnel) Sciences, technologies, santé mention Physique fondamentale et applications parcours Physique médicale | F23: Science, Technology, Health (STS) – major: Physics Fundamental & Applications – track: Medical Physics | G23: Master indifférencié (recherche et professionnel) | H23: Campus scientifique de BEAULIEU | I23: Université de Rennes | J23: Site de Rennes - FDS Faculté des sciences | L23: Public university | M23: French | N23: General | O23: Bac +4 | P23: Eligible on level (4-yr BS ≈ Bac+4) | Q23: 1 | R23: 12 | S23: 3950 | T23: 255 | U23: 2 | V23: =IF(S23="","",S23*U23) | W23: Catalogue: €3,950. = national differentiated master fee (2026-27: €3,950). Exemption to ~€255 possible (university quota). | X23: High | Y23: 3950 | Z23: ption, il faudra vous acquitter obligatoirement des frais d'inscription s’élevant à 3 950 Euros | AC23: Open | AD23: 2026-10-01 | AE23: 2027-03-15 | AF23: No | AG23: https://formations.univ-rennes.fr/ | AH23: Formations ou matières qu'il faut avoir déjà suivi au cours de son cursus antérieur : Licence de physique ou physique chimie, sciences des matériaux, master 1 en physique, bon socle en mathématiques. Niveau spécifique at | AI23: Open in EEF
A24: 23 | B24: ★★★★★ | C24: 5 – Core fit (embedded/biomedical/health tech) | D24: Biomedical / Health tech | E24: Master indifférencié (recherche et professionnel) Sciences, technologies, santé mention Sciences et génie des matériaux parcours Ingénierie Biomédicale, Biomatériaux, Biomolécules | F24: Science, Technology, Health (STS) – major: Sciences & Engineering of Materials – track: Biomedical Engineering, Biomaterials, Biomolecules | G24: Master indifférencié (recherche et professionnel) | H24: Institut Galilée | I24: Université Sorbonne Paris Nord | J24: Site de Villetaneuse | L24: Public school / institute | M24: French | N24: General | O24: Bac +4 / Bac +5 | P24: Eligible on level (4-yr BS ≈ Bac+4) | Q24: 1/2 | R24: 12 | S24: 3950 | T24: 255 | U24: 2 | V24: =IF(S24="","",S24*U24) | W24: Catalogue: €3,770. = national differentiated master fee (2026-27: €3,950). Exemption to ~€255 possible (university quota). | X24: High | Y24: 3950/3770 | Z24: sitaire 2024-2025 et devront s'acquitter des mêmes frais que les étudiants nationaux (250 euros + CVEC) L'information concernant une exonération | AC24: Open | AD24: 2026-10-01 | AE24: 2027-03-15 | AF24: No | AG24: http://www-galilee.univ-paris13.fr/ | AH24: Niveau TCF Minimun C1 bon niveau d'anglais Diplome scientifique chimie, physique-chimie, biologie ou science technologique et santé ou diplôme équivalent. Etudiant en filières médicales et odontologiques ou filières équi | AI24: Open in EEF
A25: 24 | B25: ★★★★★ | C25: 5 – Core fit (embedded/biomedical/health tech) | D25: Biomedical / Health tech | E25: Master Ingénierie de la santé BioTesting et Biomédicaments | F25: Master Health Engineering BioTesting & Biodrugs | G25: Master indifférencié (recherche et professionnel) | H25: UFR Sciences et Techniques | I25: Université de Rouen | J25: Site de Mont-Saint-Aignan | L25: Public university | M25: French | N25: General | O25: Bac +4 | P25: Eligible on level (4-yr BS ≈ Bac+4) | Q25: 1 | R25: 10 | S25: 3950 | T25: 255 | U25: 2 | V25: =IF(S25="","",S25*U25) | W25: Catalogue: €3,950. = national differentiated master fee (2026-27: €3,950). Exemption to ~€255 possible (university quota). | X25: High | Y25: 3950 | AA25: Rouen: individual exemptions up to 30% quota, priority to social/economic hardship. | AB25: https://www.univ-rouen.fr/actualites/application-des-droits-dinscription-differencies-a-luniversite-de-rouen-normandie-a-compter-de-la-rentree-universitaire-2026-2027/ | AC25: Open | AD25: 2026-10-01 | AE25: 2027-03-15 | AF25: No | AG25: https://sciences-techniques.univ-rouen.fr/offre-de-formation-les-masters--332182.kjsp?RH=1392301431998&RF=1378324428882 | AH25: B2 en français exigé. Bac +3 dans du domaine requis (licence sciences de la vie ou équivalent) | AI25: Open in EEF
A26: 25 | B26: ★★★★★ | C26: 5 – Core fit (embedded/biomedical/health tech) | D26: Biomedical / Health tech | E26: Master Ingénierie de la santé parcours Analyses et Qualité en Bio-Industries (AQBIO) | F26: Master Health Engineering – track: Analyses & Quality in Bio-Industries (AQBIO) | G26: Master indifférencié (recherche et professionnel) | H26: UFR Sciences et Techniques | I26: Université de Rouen | J26: Site de Mont-Saint-Aignan | L26: Public university | M26: French | N26: General | O26: Bac +4 | P26: Eligible on level (4-yr BS ≈ Bac+4) | Q26: 1 | R26: 10 | S26: 3950 | T26: 255 | U26: 2 | V26: =IF(S26="","",S26*U26) | W26: Catalogue: €3,950. = national differentiated master fee (2026-27: €3,950). Exemption to ~€255 possible (university quota). | X26: High | Y26: 3950 | AA26: Rouen: individual exemptions up to 30% quota, priority to social/economic hardship. | AB26: https://www.univ-rouen.fr/actualites/application-des-droits-dinscription-differencies-a-luniversite-de-rouen-normandie-a-compter-de-la-rentree-universitaire-2026-2027/ | AC26: Open | AD26: 2026-10-01 | AE26: 2027-03-15 | AF26: No | AG26: https://sciences-techniques.univ-rouen.fr/ | AH26: B2 en français exigé et Bac+3 du domaine requis. Rentrée début septembre | AI26: Open in EEF
A27: 26 | B27: ★★★★★ | C27: 5 – Core fit (embedded/biomedical/health tech) | D27: Biomedical / Health tech | E27: Master Ingénierie de la santé parcours Imagerie Cellulaire (IMAC) | F27: Master Health Engineering – track: Imaging Cellular (IMAC) | G27: Master indifférencié (recherche et professionnel) | H27: UFR Sciences et Techniques | I27: Université de Rouen | J27: Site de Mont-Saint-Aignan | L27: Public university | M27: French | N27: General | O27: Bac +4 / Bac +5 | P27: Eligible on level (4-yr BS ≈ Bac+4) | Q27: 1/2 | R27: 10 | S27: 3950 | T27: 255 | U27: 2 | V27: =IF(S27="","",S27*U27) | W27: Catalogue: €3,950. = national differentiated master fee (2026-27: €3,950). Exemption to ~€255 possible (university quota). | X27: High | Y27: 3950 | AA27: Rouen: individual exemptions up to 30% quota, priority to social/economic hardship. | AB27: https://www.univ-rouen.fr/actualites/application-des-droits-dinscription-differencies-a-luniversite-de-rouen-normandie-a-compter-de-la-rentree-universitaire-2026-2027/ | AC27: Open | AD27: 2026-10-01 | AE27: 2027-03-15 | AF27: No | AG27: https://sciences-techniques.univ-rouen.fr/ | AH27: B2 en français exigé. Rentrée début septembre. Pour une entrée en master 1 niveau Bac + 3 dans le domaine requis. Pour une entrée en Master 2, Bac + 4 dans le domaine requis. Ce master est un master spécialisé sur deux a | AI27: Open in EEF
A28: 27 | B28: ★★★★★ | C28: 5 – Core fit (embedded/biomedical/health tech) | D28: Biomedical / Health tech | E28: Master Ingénierie de la santé parcours Ingénierie pour le Bio-Médical | F28: Master Health Engineering – track: Engineering for the Bio-Médical | G28: Master indifférencié (recherche et professionnel) | H28: UFR Sciences et Techniques | I28: Université de Rouen | J28: Saint-Etienne-du-Rouvray | L28: Public university | M28: French | N28: General | O28: Bac +4 / Bac +5 | P28: Eligible on level (4-yr BS ≈ Bac+4) | Q28: 1/2 | R28: 10 | S28: 3950 | T28: 255 | U28: 2 | V28: =IF(S28="","",S28*U28) | W28: Catalogue: €3,950. = national differentiated master fee (2026-27: €3,950). Exemption to ~€255 possible (university quota). | X28: High | Y28: 3950 | AA28: Rouen: individual exemptions up to 30% quota, priority to social/economic hardship. | AB28: https://www.univ-rouen.fr/actualites/application-des-droits-dinscription-differencies-a-luniversite-de-rouen-normandie-a-compter-de-la-rentree-universitaire-2026-2027/ | AC28: Open | AD28: 2026-10-01 | AE28: 2027-03-15 | AF28: No | AG28: http://sciences-techniques.univ-rouen.fr/ | AH28: B2 en français exigé. Rentrée début septembre. | AI28: Open in EEF
A29: 28 | B29: ★★★★★ | C29: 5 – Core fit (embedded/biomedical/health tech) | D29: Embedded systems / Electronics | E29: Master mention Génie industriel [Electronique embarquée et systèmes de communication] | F29: Master – major: Industrial Engineering [Embedded Electronics & Systems of Communication] | G29: Master indifférencié (recherche et professionnel) | H29: UFR Systèmes industriels et techniques de communication (Ville d'Avray) | I29: Université Paris Nanterre | J29: Site de Ville-d'Avray | L29: Public university | M29: French | N29: General | O29: Bac +4 | P29: Eligible on level (4-yr BS ≈ Bac+4) | Q29: 1 | S29: 3950 | T29: 255 | U29: 2 | V29: =IF(S29="","",S29*U29) | W29: Catalogue: €3,950. = national differentiated master fee (2026-27: €3,950). Exemption to ~€255 possible (university quota). | X29: High | Y29: 3950 | AC29: Open | AD29: 2026-10-01 | AE29: 2027-03-15 | AF29: No | AG29: https://ufr-sitec.parisnanterre.fr/ | AH29: Les candidats non francophones ou ressortissant d'un pays ou le français n'est pas langue officielle doivent impérativement justifier de leur niveau de français en produisant dans leur dossier le TCF niveau C1 ou le DALF | AI29: Open in EEF
A30: 29 | B30: ★★★★★ | C30: 5 – Core fit (embedded/biomedical/health tech) | D30: Embedded systems / Electronics | E30: Master Sciences, technologies, santé, mention Electronique, énergie électrique, automatique Orientations CIM (Capteurs intelligents et micro-nano-technologies) et EMB (Électronique Embarquée) | F30: Master Science, Technology, Health (STS), – major: Electronics, Electrical Energy & Automation (EEA) Orientations CIM (Sensors Intelligent & micro-nano-technologies) & EMB (Embedded Electronics) | G30: Master indifférencié (recherche et professionnel) | H30: Faculté des Sciences et Technologies | I30: Université de Lorraine | J30: Site de Vandoeuvre-lès-Nancy | L30: Public university | M30: French | N30: General | O30: Bac +4 | P30: Eligible on level (4-yr BS ≈ Bac+4) | Q30: 1 | S30: 3950 | T30: 255 | U30: 2 | V30: =IF(S30="","",S30*U30) | W30: Catalogue: €3,950. = national differentiated master fee (2026-27: €3,950). Exemption to ~€255 possible (university quota). | X30: High | Y30: 3950 | AC30: Open | AD30: 2026-10-01 | AE30: 2027-03-15 | AF30: No | AG30: https://fst.univ-lorraine.fr/formations/ | AH30: Pour le Master 1 : Niveau licence en électronique, électrotechnique, Automatique, Informatique industrielle exigé. Niveau B2 en langue française exigé. Aucun dossier transmis en dehors de la campagne d'ouverture de Campu | AI30: Open in EEF
A31: 30 | B31: ★★★★★ | C31: 5 – Core fit (embedded/biomedical/health tech) | D31: Biomedical / Health tech | E31: Master Sciences, technologies, santé, mention Ingénierie de la santé | F31: Master Science, Technology, Health (STS), – major: Health Engineering | G31: Master indifférencié (recherche et professionnel) | H31: Faculté de Santé | I31: Université Jean Monnet Saint-Etienne | J31: Site de Saint-Etienne | K31: 42270 Saint-Priest-en-Jarez | L31: Public university | M31: French | N31: General | O31: Bac +4 | P31: Eligible on level (4-yr BS ≈ Bac+4) | Q31: 1 | S31: 3950 | T31: 255 | U31: 2 | V31: =IF(S31="","",S31*U31) | W31: Catalogue: €3,950. = national differentiated master fee (2026-27: €3,950). Exemption to ~€255 possible (university quota). | X31: High | Y31: 3950 | Z31: Master : 3950 € + le paiement de la CVEC : 105 € (tarif indicatif 2026/2027) | AC31: Open | AD31: 2026-10-01 | AE31: 2027-03-15 | AF31: No | AG31: https://medecine.univ-st-etienne.fr/fr/formation-initiale/licence-masters.html | AH31: Niveaux de langues : B2 minimum en Français et en Anglais | AI31: Open in EEF
A32: 31 | B32: ★★★★★ | C32: 5 – Core fit (embedded/biomedical/health tech) | D32: Biomedical / Health tech | E32: Master Sciences, technologies, santé, mention Ingénierie de la santé parcours Dispositif médical et affaires réglementaires | F32: Master Science, Technology, Health (STS), – major: Health Engineering – track: Dispositif Medical & affaires réglementaires | G32: Master indifférencié (recherche et professionnel) | H32: Université de technologie de Compiègne | J32: Site de Compiègne | L32: Public university | M32: French | N32: General | O32: Bac +4 / Bac +5 | P32: Eligible on level (4-yr BS ≈ Bac+4) | Q32: 1/2 | S32: 3950 | T32: 255 | U32: 2 | V32: =IF(S32="","",S32*U32) | W32: Catalogue: €3,950. = national differentiated master fee (2026-27: €3,950). Exemption to ~€255 possible (university quota). | X32: High | Y32: 3950 | AC32: Open | AD32: 2026-10-01 | AE32: 2027-03-15 | AF32: No | AG32: https://www.utc.fr/formations/diplome-de-master/mention-ingenierie-de-la-sante-ids/parcours-dispositif-medical-et-affaires-reglementaires-dmar/ | AH32: Pour les parcours DMAR et TBTS Attention, le recrutement en M1 est commun. Ainsi, en candidatant sur l’un vous candidatez également sur l’autre, pas besoin de déposer votre dossier de candidature deux fois. Mentions de l | AI32: Open in EEF
A33: 32 | B33: ★★★★★ | C33: 5 – Core fit (embedded/biomedical/health tech) | D33: Biomedical / Health tech | E33: Master Sciences, technologies, santé, mention Ingénierie de la santé parcours Ingénierie des formations en santé (IFS) | F33: Master Science, Technology, Health (STS), – major: Health Engineering – track: Engineering of formations in Health (IFS) | G33: Master indifférencié (recherche et professionnel) | H33: UFR de santé médecine biologie humaine - Léonard de Vinci | I33: Université Sorbonne Paris Nord | J33: Site de Bobigny | L33: Public university | M33: French | N33: General | O33: Bac +4 / Bac +5 | P33: Eligible on level (4-yr BS ≈ Bac+4) | Q33: 1/2 | S33: 3950 | T33: 255 | U33: 2 | V33: =IF(S33="","",S33*U33) | W33: Catalogue: €3,950. = national differentiated master fee (2026-27: €3,950). Exemption to ~€255 possible (university quota). | X33: High | Y33: 3950 | AC33: Open | AD33: 2026-10-01 | AE33: 2027-03-15 | AF33: No | AI33: Open in EEF
A34: 33 | B34: ★★★★★ | C34: 5 – Core fit (embedded/biomedical/health tech) | D34: Biomedical / Health tech | E34: Master Sciences, technologies, santé, mention Ingénierie de la santé parcours Qualité, sécurité des parcours de soins (QSPS) | F34: Master Science, Technology, Health (STS), – major: Health Engineering – track: Quality, Security of – track: of soins (QSPS) | G34: Master indifférencié (recherche et professionnel) | H34: UFR de santé médecine biologie humaine - Léonard de Vinci | I34: Université Sorbonne Paris Nord | J34: Site de Bobigny | L34: Public university | M34: French | N34: General | O34: Bac +4 | P34: Eligible on level (4-yr BS ≈ Bac+4) | Q34: 1 | S34: 3950 | T34: 255 | U34: 2 | V34: =IF(S34="","",S34*U34) | W34: Catalogue: €3,950. = national differentiated master fee (2026-27: €3,950). Exemption to ~€255 possible (university quota). | X34: High | Y34: 3950 | AC34: Open | AD34: 2026-10-01 | AE34: 2027-03-15 | AF34: No | AI34: Open in EEF
A35: 34 | B35: ★★★★★ | C35: 5 – Core fit (embedded/biomedical/health tech) | D35: Biomedical / Health tech | E35: Master Sciences, technologies, santé mention sciences et techniques des activités physiques et sportives spécialité ingénierie de la rééducation, du handicap et de la performance motrice | F35: Master Science, Technology, Health (STS) – major: Sciences & Techniques of activités physiques & sportives – specialisation: Engineering of the rééducation, of handicap & of the Performance motrice | G35: Master indifférencié (recherche et professionnel) | H35: UFR de sciences et techniques | I35: Le Mans Université | J35: UFR STS - Le Mans | K35: 72085 LE MANS CEDEX | L35: Public university | M35: French | N35: General | O35: Bac +4 / Bac +5 | P35: Eligible on level (4-yr BS ≈ Bac+4) | Q35: 1/2 | R35: 12 | S35: 3950 | T35: 255 | U35: 2 | V35: =IF(S35="","",S35*U35) | W35: Catalogue: €3,950. = national differentiated master fee (2026-27: €3,950). Exemption to ~€255 possible (university quota). | X35: High | Y35: 3950 | AA35: Le Mans governance formally opposed the decree; exemption policy not published. | AB35: https://www.letudiant.fr/educpros/actualite/droits-d-inscription-majores-pour-les-etudiants-etrangers-pourquoi-l-application-du-decret-met-en-difficulte-de-nombreuses-universites.html | AC35: Open | AD35: 2026-10-01 | AE35: 2027-03-15 | AF35: No | AG35: http://sciences.univ-lemans.fr | AH35: TCF B2 minimum Pour candidature en M1 STAPS APAS : Licence 3 STAPS APAS déjà validée ou diplôme équivalent. | AI35: Open in EEF
A36: 35 | B36: ★★★★★ | C36: 5 – Core fit (embedded/biomedical/health tech) | D36: Signal / Image / Vision | E36: Master Sciences, technologies, santé, Optique, image, vision, mutlimédia parcours M2 Signaux et image en médecine (SIM) | F36: Master Science, Technology, Health (STS), Optics, Image, Vision, Multimedia – track: M2 Signaux & Image in Medicine (SIM) | G36: Master indifférencié (recherche et professionnel) | H36: UFR des sciences et technologie | I36: Université Paris-Est Créteil Val-de-Marne | J36: Site de Créteil | L36: Public university | M36: French | N36: General | O36: Bac +4 / Bac +5 | P36: Eligible on level (4-yr BS ≈ Bac+4) | Q36: 1/2 | R36: 12 | S36: 3950 | T36: 255 | U36: 2 | V36: =IF(S36="","",S36*U36) | W36: Catalogue: €3,950. = national differentiated master fee (2026-27: €3,950). Exemption to ~€255 possible (university quota). | X36: High | Y36: 3950 | AC36: Open | AD36: 2026-10-01 | AE36: 2027-03-15 | AF36: No | AG36: https://sciences-tech.u-pec.fr/formation/master-optique-image-vision-multimedia-parcours-signaux-et-image-en-medecine-sim | AH36: C2 ( C1 si anglophone) , Etre titulaire d'un master 1 en Sciences pour l'Ingénieur avec de bons résultats en Mathématiques, Programmation et Data Science. Pré-requis indispensable : avoir reçu un enseignement des fondame | AI36: Open in EEF
A37: 36 | B37: ★★★★★ | C37: 5 – Core fit (embedded/biomedical/health tech) | D37: Signal / Image / Vision | E37: Master Sciences, technologies, santé, Optique, image, vision, mutlimédia parcours M2 Intelligence artificielle, Science des données et systèmes cyber-physiques (IA2S) | F37: Master Science, Technology, Health (STS), Optics, Image, Vision, Multimedia – track: M2 Artificial Intelligence, Data Science & Systems cyber-physiques (IA2S) | G37: Master indifférencié (recherche et professionnel) | H37: UFR des sciences et technologie | I37: Université Paris-Est Créteil Val-de-Marne | J37: Site de Créteil | L37: Public university | M37: French | N37: General | O37: Bac +4 / Bac +5 | P37: Eligible on level (4-yr BS ≈ Bac+4) | Q37: 1/2 | R37: 10 | S37: 3950 | T37: 255 | U37: 2 | V37: =IF(S37="","",S37*U37) | W37: Catalogue: €3,950. = national differentiated master fee (2026-27: €3,950). Exemption to ~€255 possible (university quota). | X37: High | Y37: 3950 | AC37: Open | AD37: 2026-10-01 | AE37: 2027-03-15 | AF37: No | AG37: https://sciences-tech.u-pec.fr/formation/master-optique-image-vision-multimedia-parcours-intelligence-artificielle-sciences-des-donnees-et-systemes-cyber-physiques-ia2s | AI37: Open in EEF
A38: 37 | B38: ★★★★★ | C38: 5 – Core fit (embedded/biomedical/health tech) | D38: IoT / Telecom / Networks | E38: Master Sciences, technologies, santé, Traitement du signal et des images parcours Objets connectés | F38: Master Science, Technology, Health (STS), Signal & Image Processing – track: Connected Objects (IoT) | G38: Master indifférencié (recherche et professionnel) | H38: UFR de sciences fondamentales et appliquées - Université de Poitiers | I38: Université de Poitiers | J38: Site de Poitiers | L38: Public university | M38: French | N38: General | O38: Bac +4 / Bac +5 | P38: Eligible on level (4-yr BS ≈ Bac+4) | Q38: 1/2 | S38: 3950 | T38: 255 | U38: 2 | V38: =IF(S38="","",S38*U38) | W38: Catalogue: €3,950. = national differentiated master fee (2026-27: €3,950). Exemption to ~€255 possible (university quota). | X38: High | Y38: 3950 | AC38: Open | AD38: 2026-10-01 | AE38: 2027-03-15 | AF38: No | AG38: https://sfa.univ-poitiers.fr/formation/offre-de-formation-sciences-technologies-sante/ | AH38: Année 1 L'attention de la commission de recrutement sera portée notamment sur les résultats obtenus sur les matières en lien avec la discipline visée et sur l'aptitude du candidat à exposer ses motivations et son projet | AI38: Open in EEF
A39: 38 | B39: ★★★★★ | C39: 5 – Core fit (embedded/biomedical/health tech) | D39: Embedded systems / Electronics | E39: Master Systèmes intelligents, Mobiles et Embarqués (SIME) | F39: Master Systems Intelligent, Mobile & Embedded (SIME) | G39: Master indifférencié (recherche et professionnel) | H39: UFR Sciences et Techniques | I39: Université de Rouen | J39: Saint-Etienne-du-Rouvray | L39: Public university | M39: French | N39: General | O39: Bac +4 / Bac +5 | P39: Eligible on level (4-yr BS ≈ Bac+4) | Q39: 1/2 | R39: 10 | S39: 3950 | T39: 255 | U39: 2 | V39: =IF(S39="","",S39*U39) | W39: Catalogue: €3,950. = national differentiated master fee (2026-27: €3,950). Exemption to ~€255 possible (university quota). | X39: High | Y39: 3950 | AA39: Rouen: individual exemptions up to 30% quota, priority to social/economic hardship. | AB39: https://www.univ-rouen.fr/actualites/application-des-droits-dinscription-differencies-a-luniversite-de-rouen-normandie-a-compter-de-la-rentree-universitaire-2026-2027/ | AC39: Open | AD39: 2026-10-01 | AE39: 2027-03-15 | AF39: No | AG39: http://sciences-techniques.univ-rouen.fr/ | AH39: Master mention Science des Données sur 2 ans constitué de deux parcours au choix à partir de la 1ère année : - Apprentissage Automatique pour l'Intelligence Artificielle (A2IA) - Systèmes Intelligents Mobiles et Embarqué | AI39: Open in EEF
A40: 39 | B40: ★★★★★ | C40: 5 – Core fit (embedded/biomedical/health tech) | D40: Biomedical / Health tech | E40: Master BioMedical Engineering | F40: Master BioMedical Engineering | G40: Master indifférencié (recherche et professionnel) | H40: UFR des Sciences pharmaceutiques et biologiques | I40: Université de Montpellier | J40: Site de Montpellier | K40: 34090 Montpellier | L40: Public university | M40: French | N40: General | O40: Bac +4 | P40: Eligible on level (4-yr BS ≈ Bac+4) | Q40: 1 | R40: 12 | S40: 3950 | T40: 255 | U40: 2 | V40: =IF(S40="","",S40*U40) | W40: Not in catalogue. Public national master → 2026-27 differentiated fee €3,950; exemption to ~€254-255 depends on university quota (25% cap in 2027-28). | X40: Medium | AA40: Montpellier 2026-27: new non-EU entrants pay the differentiated fee unless individual exemption (limited). | AB40: https://www.umontpellier.fr/en/international/etudier-a-letranger/etudiants-internationaux-annee-universitaire-2026-2027/ | AC40: Open | AD40: 2026-10-01 | AE40: 2027-03-15 | AF40: No | AG40: https://idil.edu.umontpellier.fr/master-idil/les-parcours/ | AH40: Conditions d’accès Diplôme de licence dans la discipline choisie IDIL Niveau d’anglais B2 minimum CV et lettre de motivation 2 lettres de soutien d’un chercheur et/ou professeur (recommandé, mais non obligatoire) Estimat | AI40: Open in EEF
...

Sheet Summary
A1: Field | B1: Programs | C1: Eligible on level | D1: Taught in English (incl. FR&EN) | E1: Est. fee ≤ €4,000 | F1: Est. fee > €6,000 | G1: Cheapest est. fee (€, excl. apprenticeship €0)
